Workbook
Name \a: '[1]2001'!$P$1:$Q$3
Name con: #REF!
Name con: #REF!
Name con: #REF!
Name con: #REF!
Name con: #REF!
Name con: #REF!
Name con: #REF!
Name contador: #REF!
Name contador: #REF!
Name contador: #REF!
Name contador: #REF!
Name contador: #REF!
Name contador: #REF!
Name contador: #REF!
Name contador: #REF!
Name contador: #REF!
Name contador: #REF!
Name contador: #REF!
Name contador: #REF!
Name contador: #REF!

Sheet ENERO
A3: TRANSFERENCIAS DE FONDOS
A4: MES DE ENERO 2021
N5: (En pesos)
A6: Municipio | B6: ENERO 2021
B7: Coparticipación Bruta | C7: Omisión Coparticiación 2020 | D7: Descentralización | E7: Juegos de Azar | F7: F.F.P.S. (Programas Sociales) | G7: F.S.A. (Tratamiento de Residuos) | H7: Fondo Fort. Recursos Municipales | I7: Fondo Inclusión Social | J7: Fondo de Financ. Educativo | K7: Fdo. Para Infrestructura Municipal 2016 | L7: Fdo. Para Infrestructura Municipal 2017 | M7: Fdo Ley 14890 | N7: Total
A8: ADOLFO ALSINA | B8: 55728656 | C8: 0 | D8: 1562456.1 | E8: 0 | F8: 135767.53 | G8: 75829.11 | H8: 2574935.8 | I8: 401281.21 | J8: 5562179.2 | K8: 0 | L8: 0 | M8: 31.6 | N8: =SUM(B8:M8) -> 66041137
A9: ADOLFO GONZALES CHAVES | B9: 34743303 | C9: 0 | D9: 1691683 | E9: 0 | F9: 95121.6 | G9: 53567.35 | H9: 1605310.1 | I9: 281146.09 | J9: 4174638.2 | K9: 0 | L9: 0 | M9: 22.13 | N9: =SUM(B9:M9) -> 42644792
A10: ALBERTI | B10: 25533412 | C10: 0 | D10: 720484.33 | E10: 0 | F10: 66450.19 | G10: 47306.23 | H10: 1179768.2 | I10: 196403.47 | J10: 2467499 | K10: 0 | L10: 0 | M10: 15.46 | N10: =SUM(B10:M10) -> 30211339
A11: ALMIRANTE BROWN | B11: 2.9567931e+08 | C11: 0 | D11: 1995189.7 | E11: 0 | F11: 7132433.6 | G11: 4406094 | H11: 13661826 | I11: 21080972 | J11: 46439925 | K11: 0 | L11: 0 | M11: 1660.32 | N11: =SUM(B11:M11) -> 3.9039741e+08
A12: ARRECIFES | B12: 44379841 | C12: 0 | D12: 2033966.8 | E12: 0 | F12: 243875.59 | G12: 129396.46 | H12: 2050565.2 | I12: 720810.71 | J12: 5009705.2 | K12: 0 | L12: 0 | M12: 56.76 | N12: =SUM(B12:M12) -> 54568218
A13: AVELLANEDA | B13: 1.7942506e+08 | C13: 0 | D13: 1783827.1 | E13: 0 | F13: 3468396.7 | G13: 965282.63 | H13: 8290312.9 | I13: 10251364 | J13: 35706454 | K13: 0 | L13: 0 | M13: 807.39 | N13: =SUM(B13:M13) -> 2.398915e+08
A14: AYACUCHO | B14: 65025299 | C14: 0 | D14: 2672767.6 | E14: 0 | F14: 157861.38 | G14: 90438.38 | H14: 3004486 | I14: 466582.87 | J14: 7186502.2 | K14: 0 | L14: 0 | M14: 36.74 | N14: =SUM(B14:M14) -> 78603974
A15: AZUL | B15: 1.0597205e+08 | C15: 0 | D15: 3155687.3 | E15: 0 | F15: 588101.1 | G15: 290794.19 | H15: 4896425.8 | I15: 1738220.6 | J15: 11998767 | K15: 0 | L15: 0 | M15: 136.89 | N15: =SUM(B15:M15) -> 1.2864019e+08
A16: BAHIA BLANCA | B16: 1.9587942e+08 | C16: 0 | D16: 3922833 | E16: 0 | F16: 2193362.5 | G16: 1342662.1 | H16: 9050584.6 | I16: 6482810 | J16: 29744581 | K16: 0 | L16: 0 | M16: 510.58 | N16: =SUM(B16:M16) -> 2.4861676e+08
A17: BALCARCE | B17: 70382565 | C17: 0 | D17: 2555143.8 | E17: 0 | F17: 450478.36 | G17: 194790.36 | H17: 3252017.9 | I17: 1331456 | J17: 8203245.2 | K17: 0 | L17: 0 | M17: 104.86 | N17: =SUM(B17:M17) -> 86369802
A18: BARADERO | B18: 43151097 | C18: 0 | D18: 1587620.7 | E18: 0 | F18: 303579.58 | G18: 146092.77 | H18: 1993791.2 | I18: 897274.74 | J18: 6623722 | K18: 0 | L18: 0 | M18: 70.66 | N18: =SUM(B18:M18) -> 54703249
A19: BENITO JUAREZ | B19: 72187283 | C19: 0 | D19: 1785868.9 | E19: 0 | F19: 122612.41 | G19: 90438.38 | H19: 3335404.7 | I19: 362399.3 | J19: 5627556.6 | K19: 0 | L19: 0 | M19: 28.53 | N19: =SUM(B19:M19) -> 83511592
... A142: ZARATE | B142: 79950840 | C142: 0 | D142: 1500710.5 | E142: 0 | F142: 1606104.6 | G142: 508541.98 | H142: 3694118.9 | I142: 4747081.9 | J142: 14110989 | K142: 0 | L142: 0 | M142: 373.87 | N142: =SUM(B142:M142) -> 1.0611876e+08
A143: CONSOLIDADO 135 MUNICIPIOS | B143: =SUM(B8:B142) -> 1.4221573e+10 | C143: =SUM(C8:C142) -> 0 | D143: =SUM(D8:D142) -> 2.3138881e+08 | E143: =SUM(E8:E142) -> 0 | F143: =SUM(F8:F142) -> 1.6865532e+08 | G143: =SUM(G8:G142) -> 69567987 | H143: =SUM(H8:H142) -> 6.5710606e+08 | I143: =SUM(I8:I142) -> 4.9848597e+08 | ... N143: =SUM(N8:N142) -> 1.7590681e+10

Sheet FEBRERO
A3: TRANSFERENCIAS DE FONDOS
A4: MES DE FEBRERO 2021
N5: (En pesos)
A6: Municipio | B6: FEBRERO 2021
B7: Coparticipación Bruta | C7: Omisión Coparticiación 2020 | D7: Descentralización | E7: Juegos de Azar | F7: F.F.P.S. (Programas Sociales) | G7: F.S.A. (Tratamiento de Residuos) | H7: Fondo Fort. Recursos Municipales | I7: Fondo Inclusión Social | J7: Fondo de Financ. Educativo | K7: Fdo. Para Infrestructura Municipal 2016 | L7: Fdo. Para Infrestructura Municipal 2017 | M7: Fdo Ley 14890 | N7: Total
A8: ADOLFO ALSINA | B8: 56023120 | D8: 1574395.4 | E8: 474630.95 | F8: 141268.26 | G8: 73617.38 | H8: 3101061.2 | I8: 480938.81 | J8: 5005961.3 | K8: 0 | L8: 0 | M8: 0.3 | N8: =SUM(B8:M8) -> 66874994
A9: ADOLFO GONZALES CHAVES | B9: 34926883 | D9: 1225022.6 | E9: 293763.03 | F9: 98975.52 | G9: 52004.94 | H9: 1933316.1 | I9: 336955.89 | J9: 3757174.4 | K9: 0 | L9: 0 | M9: 0.21 | N9: =SUM(B9:M9) -> 42624095
A10: ALBERTI | B10: 25668328 | D10: 673153.18 | E10: 219370.07 | F10: 69142.47 | G10: 45926.44 | H10: 1420825.1 | I10: 235391.17 | J10: 2220749.1 | K10: 0 | L10: 0 | M10: 0.15 | N10: =SUM(B10:M10) -> 30552886
A11: ALMIRANTE BROWN | B11: 2.9724164e+08 | D11: 2552420.6 | E11: 3526341.9 | F11: 7421409.6 | G11: 4288418.9 | H11: 16453288 | I11: 25265717 | J11: 41795932 | K11: 0 | L11: 0 | M11: 16.2 | N11: =SUM(B11:M11) -> 3.9854518e+08
A12: ARRECIFES | B12: 44614339 | D12: 1143533 | E12: 376394.91 | F12: 253756.4 | G12: 125622.32 | H12: 2469548.2 | I12: 863897.54 | J12: 4508734.7 | K12: 0 | L12: 0 | M12: 0.55 | N12: =SUM(B12:M12) -> 54355827
A13: AVELLANEDA | B13: 1.8037312e+08 | D13: 2079300.3 | E13: 2151192.3 | F13: 3608921.5 | G13: 964476.46 | H13: 9984236.4 | I13: 12286344 | J13: 32135808 | K13: 0 | L13: 0 | M13: 7.88 | N13: =SUM(B13:M13) -> 2.435834e+08
A14: AYACUCHO | B14: 65368885 | D14: 2164641.4 | E14: 550592.62 | F14: 164257.25 | G14: 87800.55 | H14: 3618379.6 | I14: 559203.39 | J14: 6467852 | K14: 0 | L14: 0 | M14: 0.35 | N14: =SUM(B14:M14) -> 78981612
A15: AZUL | B15: 1.06532e+08 | D15: 3054850.3 | E15: 900825.55 | F15: 611928.47 | G15: 282312.52 | H15: 5896891.2 | I15: 2083271.6 | J15: 10798890 | K15: 0 | L15: 0 | M15: 1.33 | N15: =SUM(B15:M15) -> 1.3016097e+08
A16: BAHIA BLANCA | B16: 1.9691442e+08 | D16: 4478672.7 | E16: 2339592.8 | F16: 2282228.2 | G16: 1303500.4 | H16: 10899851 | I16: 7769701 | J16: 26770123 | K16: 0 | L16: 0 | M16: 4.98 | N16: =SUM(B16:M16) -> 2.5275809e+08
A17: BALCARCE | B17: 70754459 | D17: 2958544 | E17: 595271.58 | F17: 468729.84 | G17: 189108.87 | H17: 3916488.5 | I17: 1595761 | J17: 7382920.7 | K17: 0 | L17: 0 | M17: 1.02 | N17: =SUM(B17:M17) -> 87861284
A18: BARADERO | B18: 43379102 | D18: 1313533.2 | E18: 370178.05 | F18: 315879.34 | G18: 141831.65 | H18: 2401173.9 | I18: 1075391.1 | J18: 5961349.8 | K18: 0 | L18: 0 | M18: 0.68 | N18: =SUM(B18:M18) -> 54958440
A19: BENITO JUAREZ | B19: 72568712 | D19: 1979927.8 | E19: 611621.96 | F19: 127580.15 | G19: 87800.55 | H19: 4016913.4 | I19: 434338.53 | J19: 5064800.9 | K19: 0 | L19: 0 | M19: 0.27 | N19: =SUM(B19:M19) -> 84891696
... A142: ZARATE | B142: 80373291 | D142: 1231933 | E142: 953903.15 | F142: 1671177.2 | G142: 493709.22 | H142: 4448922.1 | I142: 5689416.5 | J142: 12699890 | K142: 0 | L142: 0 | M142: 3.64 | N142: =SUM(B142:M142) -> 1.0756225e+08
A143: CONSOLIDADO 135 MUNICIPIOS | B143: =SUM(B8:B142) -> 1.4296718e+10 | C143: =SUM(C8:C142) -> 0 | D143: =SUM(D8:D142) -> 2.3631549e+08 | E143: =SUM(E8:E142) -> 1.4748019e+08 | F143: =SUM(F8:F142) -> 1.7548852e+08 | G143: =SUM(G8:G142) -> 67538881 | H143: =SUM(H8:H142) -> 7.9136968e+08 | I143: =SUM(I8:I142) -> 5.9743952e+08 | ... N143: =SUM(N8:N142) -> 1.7881829e+10

Sheet MARZO
A3: TRANSFERENCIAS DE FONDOS
A4: MES DE MARZO 2021
N5: (En pesos)
A6: Municipio | B6: MARZO 2021
B7: Coparticipación Bruta | C7: Omisión Coparticiación 2020 | D7: Descentralización | E7: Juegos de Azar | F7: F.F.P.S. (Programas Sociales) | G7: F.S.A. (Tratamiento de Residuos) | H7: Fondo Fort. Recursos Municipales | I7: Fondo Inclusión Social | J7: Fondo de Financ. Educativo | K7: Fdo. Para Infrestructura Municipal 2016 | L7: Fdo. Para Infrestructura Municipal 2017 | M7: Fdo Ley 14890 | N7: Total
A8: ADOLFO ALSINA | B8: 57548493 | C8: 0 | D8: 2333549.7 | E8: 0 | F8: 285183.41 | G8: 128679.56 | H8: 2911362.6 | I8: 450809.31 | J8: 6118397.1 | K8: 0 | L8: 0 | M8: 27.31 | N8: =SUM(B8:M8) -> 69776502
A9: ADOLFO GONZALES CHAVES | B9: 35877856 | C9: 0 | D9: 1469444.2 | E9: 0 | F9: 199805.52 | G9: 90902.07 | H9: 1815051 | I9: 315846.52 | J9: 4592102 | K9: 0 | L9: 0 | M9: 19.14 | N9: =SUM(B9:M9) -> 44361027
A10: ALBERTI | B10: 26367214 | C10: 0 | D10: 957955.84 | E10: 0 | F10: 139580.45 | G10: 80277.16 | H10: 1333910.2 | I10: 220644.56 | J10: 2714248.9 | K10: 0 | L10: 0 | M10: 13.37 | N10: =SUM(B10:M10) -> 31813844
A11: ALMIRANTE BROWN | B11: 3.053348e+08 | C11: 0 | D11: 2298253.6 | E11: 0 | F11: 14981872 | G11: 7179828.3 | H11: 15446805 | I11: 23682889 | J11: 51083918 | K11: 0 | L11: 0 | M11: 1435.86 | N11: =SUM(B11:M11) -> 4.200098e+08
A12: ARRECIFES | B12: 45829078 | C12: 0 | D12: 1354851.6 | E12: 0 | F12: 512267.35 | G12: 219581.63 | H12: 2318480.6 | I12: 809776.73 | J12: 5510675.7 | K12: 0 | L12: 0 | M12: 49.08 | N12: =SUM(B12:M12) -> 56554761
A13: AVELLANEDA | B13: 1.8528423e+08 | C13: 0 | D13: 1662370.5 | E13: 0 | F13: 7285462.1 | G13: 2212213.7 | H13: 9373479.1 | I13: 11516638 | J13: 39277099 | K13: 0 | L13: 0 | M13: 698.23 | N13: =SUM(B13:M13) -> 2.566122e+08
A14: AYACUCHO | B14: 67148720 | C14: 0 | D14: 3008302.6 | E14: 0 | F14: 331592.14 | G14: 153471.03 | H14: 3397035.5 | I14: 524170.83 | J14: 7905152.4 | K14: 0 | L14: 0 | M14: 31.76 | N14: =SUM(B14:M14) -> 82468476
A15: AZUL | B15: 1.094326e+08 | C15: 0 | D15: 3363703.2 | E15: 0 | F15: 1235322.5 | G15: 493468.4 | H15: 5536165.6 | I15: 1952760.3 | J15: 13198644 | K15: 0 | L15: 0 | M15: 118.38 | N15: =SUM(B15:M15) -> 1.3521278e+08
A16: BAHIA BLANCA | B16: 2.0227592e+08 | C16: 0 | D16: 3660471.4 | E16: 0 | F16: 4607217.8 | G16: 2278454.6 | H16: 10233084 | I16: 7282950.4 | J16: 32719039 | K16: 0 | L16: 0 | M16: 441.54 | N16: =SUM(B16:M16) -> 2.6305758e+08
A17: BALCARCE | B17: 72680929 | C17: 0 | D17: 3214149.5 | E17: 0 | F17: 946242.12 | G17: 330552.99 | H17: 3676908.5 | I17: 1495790.9 | J17: 9023569.7 | K17: 0 | L17: 0 | M17: 90.68 | N17: =SUM(B17:M17) -> 91368234
A18: BARADERO | B18: 44560209 | C18: 0 | D18: 1075059.8 | E18: 0 | F18: 637677.21 | G18: 247914.75 | H18: 2254288.9 | I18: 1008020.8 | J18: 7286094.2 | K18: 0 | L18: 0 | M18: 61.09 | N18: =SUM(B18:M18) -> 57069326
A19: BENITO JUAREZ | B19: 74544581 | C19: 0 | D19: 2421948.2 | E19: 0 | F19: 257550.73 | G19: 153471.03 | H19: 3771190.1 | I19: 407128.41 | J19: 6190312.3 | K19: 0 | L19: 0 | M19: 24.66 | N19: =SUM(B19:M19) -> 87746206
... A142: ZARATE | B142: 82561659 | C142: 0 | D142: 942074.29 | E142: 0 | F142: 3373666.7 | G142: 862979.42 | H142: 4176771.9 | I142: 5332990.2 | J142: 15522087 | K142: 0 | L142: 0 | M142: 323.32 | N142: =SUM(B142:M142) -> 1.1277255e+08
A143: CONSOLIDADO 135 MUNICIPIOS | B143: =SUM(B8:B142) -> 1.4685983e+10 | C143: =SUM(C8:C142) -> 0 | D143: =SUM(D8:D142) -> 2.3660926e+08 | E143: =SUM(E8:E142) -> 0 | F143: =SUM(F8:F142) -> 3.5426512e+08 | G143: =SUM(G8:G142) -> 1.1805464e+08 | H143: =SUM(H8:H142) -> 7.4295989e+08 | I143: =SUM(I8:I142) -> 5.6001157e+08 | ... N143: =SUM(N8:N142) -> 1.8616169e+10

Sheet ABRIL
A3: TRANSFERENCIAS DE FONDOS
A4: MES DE ABRIL 2021
N5: (En pesos)
A6: Municipio | B6: ABRIL 2021
B7: Coparticipación Bruta | C7: Omisión Coparticiación 2020 | D7: Descentralización | E7: Juegos de Azar | F7: F.F.P.S. (Programas Sociales) | G7: F.S.A. (Tratamiento de Residuos) | H7: Fondo Fort. Recursos Municipales | I7: Fondo Inclusión Social | J7: Fondo de Financ. Educativo | K7: Fdo. Para Infrestructura Municipal 2016 | L7: Fdo. Para Infrestructura Municipal 2017 | M7: Fdo Ley 14890 | N7: Total
A8: ADOLFO ALSINA | B8: 60472298 | C8: 0 | D8: 16967322 | E8: 0 | F8: 175243.5 | G8: 93699.18 | H8: 3097288.5 | I8: 479945.77 | J8: 5562179.2 | K8: 0 | L8: 0 | M8: 920.74 | N8: =SUM(B8:M8) -> 86848897
A9: ADOLFO GONZALES CHAVES | B9: 37700664 | C9: 0 | D9: 14384170 | E9: 0 | F9: 122779.29 | G9: 66191.16 | H9: 1930964 | I9: 336260.14 | J9: 4174638.2 | K9: 0 | L9: 0 | M9: 645.09 | N9: =SUM(B9:M9) -> 58716312
A10: ALBERTI | B10: 27706825 | C10: 0 | D10: 11697111 | E10: 0 | F10: 85771.35 | G10: 58454.53 | H10: 1419096.5 | I10: 234905.14 | J10: 2467499 | K10: 0 | L10: 0 | M10: 450.64 | N10: =SUM(B10:M10) -> 43670113
A11: ALMIRANTE BROWN | B11: 3.2084762e+08 | C11: 0 | D11: 5282537.1 | E11: 0 | F11: 9206270.4 | G11: 5345092.7 | H11: 16433271 | I11: 25213549 | J11: 46439925 | K11: 0 | L11: 0 | M11: 48370.45 | N11: =SUM(B11:M11) -> 4.2881664e+08
A12: ARRECIFES | B12: 48157468 | C12: 0 | D12: 14601802 | E12: 0 | F12: 314785.22 | G12: 159890.34 | H12: 2466543.8 | I12: 862113.78 | J12: 5009705.2 | K12: 0 | L12: 0 | M12: 1653.9 | N12: =SUM(B12:M12) -> 71573962
A13: AVELLANEDA | B13: 1.9469777e+08 | C13: 0 | D13: 2666841.8 | E13: 0 | F13: 4476872.8 | G13: 1367974.4 | H13: 9972089.5 | I13: 12260975 | J13: 35706454 | K13: 0 | L13: 0 | M13: 23521.83 | N13: =SUM(B13:M13) -> 2.611725e+08
A14: AYACUCHO | B14: 70560273 | C14: 0 | D14: 25714289 | E14: 0 | F14: 203761.38 | G14: 111751.31 | H14: 3613977.4 | I14: 558048.75 | J14: 7186502.2 | K14: 0 | L14: 0 | M14: 1070.57 | N14: =SUM(B14:M14) -> 1.0794967e+08
A15: AZUL | B15: 1.1499243e+08 | C15: 0 | D15: 40257369 | E15: 0 | F15: 759098.24 | G15: 359323.44 | H15: 5889717 | I15: 2078970.1 | J15: 11998767 | K15: 0 | L15: 0 | M15: 3988.36 | N15: =SUM(B15:M15) -> 1.7633966e+08
A16: BAHIA BLANCA | B16: 2.1255273e+08 | C16: 0 | D16: 11336623 | E16: 0 | F16: 2831107.7 | G16: 1659077.1 | H16: 10886590 | I16: 7753658.1 | J16: 29744581 | K16: 0 | L16: 0 | M16: 14874.85 | N16: =SUM(B16:M16) -> 2.7677925e+08
A17: BALCARCE | B17: 76373552 | C17: 0 | D17: 35732918 | E17: 0 | F17: 581460.11 | G17: 240695.13 | H17: 3911723.7 | I17: 1592466 | J17: 8203245.2 | K17: 0 | L17: 0 | M17: 3055.03 | N17: =SUM(B17:M17) -> 1.2663912e+08
A18: BARADERO | B18: 46824133 | C18: 0 | D18: 12358472 | E18: 0 | F18: 391848.82 | G18: 180521.35 | H18: 2398252.6 | I18: 1073170.7 | J18: 6623722 | K18: 0 | L18: 0 | M18: 2058.8 | N18: =SUM(B18:M18) -> 69852179
A19: BENITO JUAREZ | B19: 78331888 | C19: 0 | D19: 23036618 | E19: 0 | F19: 158263.38 | G19: 111751.31 | H19: 4012026.4 | I19: 433441.71 | J19: 5627556.6 | K19: 0 | L19: 0 | M19: 831.52 | N19: =SUM(B19:M19) -> 1.1171238e+08
... A142: ZARATE | B142: 86756281 | C142: 0 | D142: 9416551.1 | E142: 0 | F142: 2073098 | G142: 628386.21 | H142: 4443509.5 | I142: 5677669.1 | J142: 14110989 | K142: 0 | L142: 0 | M142: 10892.21 | N142: =SUM(B142:M142) -> 1.2311738e+08
A143: CONSOLIDADO 135 MUNICIPIOS | B143: =SUM(B8:B142) -> 1.5432118e+10 | D143: =SUM(D8:D142) -> 1.6720237e+09 | E143: =SUM(E8:E142) -> 0 | F143: =SUM(F8:F142) -> 2.1769379e+08 | G143: =SUM(G8:G142) -> 85962546 | H143: =SUM(H8:H142) -> 7.9040689e+08 | I143: =SUM(I8:I142) -> 5.9620593e+08 | J143: =SUM(J8:J142) -> 1743864910 | K143: =SUM(K8:K142) -> 0 | ... N143: =SUM(N8:N142) -> 2.053942e+10

Sheet MAYO
A3: TRANSFERENCIAS DE FONDOS
A4: MES DE MAYO 2021
N5: (En pesos)
A6: Municipio | B6: MAYO 2021
B7: Coparticipación Bruta | C7: Omisión Coparticiación 2020 | D7: Descentralización | E7: Juegos de Azar | F7: F.F.P.S. (Programas Sociales) | G7: F.S.A. (Tratamiento de Residuos) | H7: Fondo Fort. Recursos Municipales | I7: Fondo Inclusión Social | J7: Fondo de Financ. Educativo | K7: Fdo. Para Infrestructura Municipal 2016 | L7: Fdo. Para Infrestructura Municipal 2017 | M7: Fdo Ley 14890 | N7: Total
A8: ADOLFO ALSINA | B8: 64477404 | C8: 0 | D8: 2284744.7 | E8: 0 | F8: 162729.19 | G8: 94210.1 | H8: 3529949.9 | I8: 546271.97 | J8: 5284070.2 | K8: 0 | L8: 0 | M8: 7482.52 | N8: =SUM(B8:M8) -> 76386862
A9: ADOLFO GONZALES CHAVES | B9: 40197595 | C9: 0 | D9: 1576562.8 | E9: 0 | F9: 114011.51 | G9: 66552.09 | H9: 2200701.2 | I9: 382729.68 | J9: 3965906.3 | K9: 0 | L9: 0 | M9: 5242.39 | N9: =SUM(B9:M9) -> 48509301
A10: ALBERTI | B10: 29541859 | C10: 0 | D10: 844722.97 | E10: 0 | F10: 79646.33 | G10: 58773.27 | H10: 1617330.7 | I10: 267367.9 | J10: 2344124 | K10: 0 | L10: 0 | M10: 3662.23 | N10: =SUM(B10:M10) -> 34757487
A11: ALMIRANTE BROWN | B11: 3.420975e+08 | C11: 0 | D11: 3000225.3 | E11: 0 | F11: 8548841.9 | G11: 5541771.4 | H11: 18728841 | I11: 28697940 | J11: 44117929 | K11: 0 | L11: 0 | M11: 393091.57 | N11: =SUM(B11:M11) -> 4.5112614e+08
A12: ARRECIFES | B12: 51346957 | C12: 0 | D12: 1405671.1 | E12: 0 | F12: 292306.11 | G12: 160762.19 | H12: 2811096.2 | I12: 981253.75 | J12: 4759219.9 | K12: 0 | L12: 0 | M12: 13440.72 | N12: =SUM(B12:M12) -> 61770707
A13: AVELLANEDA | B13: 2.0759269e+08 | C13: 0 | D13: 2507812.5 | E13: 0 | F13: 4157175.1 | G13: 1186419.6 | H13: 11365095 | I13: 13955383 | J13: 33921131 | K13: 0 | L13: 0 | M13: 191154.56 | N13: =SUM(B13:M13) -> 2.7487686e+08
A14: AYACUCHO | B14: 75233510 | C14: 0 | D14: 2916710.5 | E14: 0 | F14: 189210.59 | G14: 112360.67 | H14: 4118815.4 | I14: 635168.4 | J14: 6827177.1 | K14: 0 | L14: 0 | M14: 8700.18 | N14: =SUM(B14:M14) -> 90041653
A15: AZUL | B15: 1.2260843e+08 | C15: 0 | D15: 3286052.3 | E15: 0 | F15: 704890.32 | G15: 361282.76 | H15: 6712453.9 | I15: 2366273.7 | J15: 11398829 | K15: 0 | L15: 0 | M15: 32412.12 | N15: =SUM(B15:M15) -> 1.4747062e+08
A16: BAHIA BLANCA | B16: 2.2663019e+08 | C16: 0 | D16: 5382778.7 | E16: 0 | F16: 2628935.6 | G16: 1668123.8 | H16: 12407343 | I16: 8825176.4 | J16: 28257352 | K16: 0 | L16: 0 | M16: 120883.27 | N16: =SUM(B16:M16) -> 2.8592078e+08
A17: BALCARCE | B17: 81431805 | C17: 0 | D17: 2934269.6 | E17: 0 | F17: 539937.49 | G17: 242007.59 | H17: 4458154 | I17: 1812537.2 | J17: 7793082.9 | K17: 0 | L17: 0 | M17: 24827.28 | N17: =SUM(B17:M17) -> 99236621
A18: BARADERO | B18: 49925315 | C18: 0 | D18: 1236461.7 | E18: 0 | F18: 363866.52 | G18: 181505.69 | H18: 2733265.5 | I18: 1221477.7 | J18: 6292535.9 | K18: 0 | L18: 0 | M18: 16731.19 | N18: =SUM(B18:M18) -> 61971159
A19: BENITO JUAREZ | B19: 83519842 | C19: 0 | D19: 2304869.4 | E19: 0 | F19: 146961.64 | G19: 112360.67 | H19: 4572468 | I19: 493341.27 | J19: 5346178.8 | K19: 0 | L19: 0 | M19: 6757.49 | N19: =SUM(B19:M19) -> 96502779
... A142: ZARATE | B142: 92502187 | C142: 0 | D142: 1226542.4 | E142: 0 | F142: 1925056.1 | G142: 631812.68 | H142: 5064225.1 | I142: 6462295.6 | J142: 13405439 | K142: 0 | L142: 0 | M142: 88517.59 | N142: =SUM(B142:M142) -> 1.2130608e+08
A143: CONSOLIDADO 135 MUNICIPIOS | B143: =SUM(B8:B142) -> 1.6454194e+10 | C143: =SUM(C8:C142) -> 0 | D143: =SUM(D8:D142) -> 2.7336086e+08 | E143: =SUM(E8:E142) -> 0 | F143: =SUM(F8:F142) -> 2.0214807e+08 | G143: =SUM(G8:G142) -> 86431283 | H143: =SUM(H8:H142) -> 9.0081915e+08 | I143: =SUM(I8:I142) -> 6.7859872e+08 | ... N143: =SUM(N8:N142) -> 2.0261519e+10

Sheet JUNIO
A3: TRANSFERENCIAS DE FONDOS
A4: MES DE JUNIO 2021
N5: (En pesos)
A6: Municipio | B6: JUNIO 2021
B7: Coparticipación Bruta | C7: Omisión Coparticiación 2020 | D7: Descentralización | E7: Juegos de Azar | F7: F.F.P.S. (Programas Sociales) | G7: F.S.A. (Tratamiento de Residuos) | H7: Fondo Fort. Recursos Municipales | I7: Fondo Inclusión Social | J7: Fondo de Financ. Educativo | K7: Fdo. Para Infrestructura Municipal 2016 | L7: Fdo. Para Infrestructura Municipal 2017 | M7: Fdo Ley 14890 | N7: Total
A8: ADOLFO ALSINA | B8: 70006282 | C8: 0 | D8: 2610026.1 | E8: 0 | F8: 290677.72 | G8: 135385.46 | H8: 3480208.3 | I8: 538033.62 | J8: 5840288.2 | K8: 0 | L8: 0 | M8: 11799.52 | N8: =SUM(B8:M8) -> 82912701
A9: ADOLFO GONZALES CHAVES | B9: 43644502 | C9: 0 | D9: 1894858.1 | E9: 0 | F9: 203654.94 | G9: 95639.27 | H9: 2169690.4 | I9: 376957.72 | J9: 4383370.1 | K9: 0 | L9: 0 | M9: 8266.97 | N9: =SUM(B9:M9) -> 52776940
A10: ALBERTI | B10: 32075047 | C10: 0 | D10: 846484.27 | E10: 0 | F10: 142269.59 | G10: 84460.65 | H10: 1594540.4 | I10: 263335.71 | J10: 2590874 | K10: 0 | L10: 0 | M10: 5775.12 | N10: =SUM(B10:M10) -> 37602786
A11: ALMIRANTE BROWN | B11: 3.7143204e+08 | C11: 0 | D11: 2600276.7 | E11: 0 | F11: 15270510 | G11: 7702095.1 | H11: 18464927 | I11: 28265145 | J11: 48761921 | K11: 0 | L11: 0 | M11: 619881.2 | N11: =SUM(B11:M11) -> 4.931168e+08
A12: ARRECIFES | B12: 55749911 | C12: 0 | D12: 1386116.5 | E12: 0 | F12: 522136.62 | G12: 231024.72 | H12: 2771484.2 | I12: 966455.43 | J12: 5260190.5 | K12: 0 | L12: 0 | M12: 21195.2 | N12: =SUM(B12:M12) -> 66908514
A13: AVELLANEDA | B13: 2.2539357e+08 | C13: 0 | D13: 2436214 | E13: 0 | F13: 7425822.8 | G13: 2105497.5 | H13: 11204946 | I13: 13744921 | J13: 37491776 | K13: 0 | L13: 0 | M13: 301438.99 | N13: =SUM(B13:M13) -> 3.0010419e+08
A14: AYACUCHO | B14: 81684714 | C14: 0 | D14: 3310345.6 | E14: 0 | F14: 337980.55 | G14: 161468.89 | H14: 4060775.9 | I14: 625589.41 | J14: 7545827.3 | K14: 0 | L14: 0 | M14: 13719.69 | N14: =SUM(B14:M14) -> 97740422
A15: AZUL | B15: 1.3312198e+08 | C15: 0 | D15: 3920965.7 | E15: 0 | F15: 1259122 | G15: 519184.59 | H15: 6617866.7 | I15: 2330587.9 | J15: 12598706 | K15: 0 | L15: 0 | M15: 51111.89 | N15: =SUM(B15:M15) -> 1.6041953e+08
A16: BAHIA BLANCA | B16: 2.4606352e+08 | C16: 0 | D16: 5169966.4 | E16: 0 | F16: 4695979.8 | G16: 2397192 | H16: 12232507 | I16: 8692083.6 | J16: 31231810 | K16: 0 | L16: 0 | M16: 190625.5 | N16: =SUM(B16:M16) -> 3.1067369e+08
A17: BALCARCE | B17: 88414507 | C17: 0 | D17: 3427096.5 | E17: 0 | F17: 964472.28 | G17: 347779.15 | H17: 4395332.8 | I17: 1785202.2 | J17: 8613407.5 | K17: 0 | L17: 0 | M17: 39151.1 | N17: =SUM(B17:M17) -> 1.0798695e+08
A18: BARADERO | B18: 54206364 | C18: 0 | D18: 1186702.8 | E18: 0 | F18: 649962.6 | G18: 260834.36 | H18: 2694750.2 | I18: 1203056.6 | J18: 6954908.1 | K18: 0 | L18: 0 | M18: 26384.1 | N18: =SUM(B18:M18) -> 67182963
A19: BENITO JUAREZ | B19: 90681592 | C19: 0 | D19: 2765879.6 | E19: 0 | F19: 262512.67 | G19: 161468.89 | H19: 4508035.9 | I19: 485901.17 | J19: 5908934.4 | K19: 0 | L19: 0 | M19: 10656.19 | N19: =SUM(B19:M19) -> 1.0478498e+08
... A142: ZARATE | B142: 1.0043416e+08 | C142: 0 | D142: 4275193.8 | E142: 0 | F142: 3438663.3 | G142: 907952 | H142: 4992863.5 | I142: 6364837.5 | J142: 14816538 | K142: 0 | L142: 0 | M142: 139586.81 | N142: =SUM(B142:M142) -> 1.353698e+08
A143: CONSOLIDADO 135 MUNICIPIOS | B143: =SUM(B8:B142) -> 1.7865126e+10 | D143: =SUM(D8:D142) -> 2.9418113e+08 | E143: =SUM(E8:E142) -> 0 | F143: =SUM(F8:F142) -> 3.6109034e+08 | G143: =SUM(G8:G142) -> 1.2420684e+08 | H143: =SUM(H8:H142) -> 8.8812543e+08 | I143: =SUM(I8:I142) -> 6.6836475e+08 | J143: =SUM(J8:J142) -> 1.8310582e+09 | K143: =SUM(K8:K142) -> 0 | ... N143: =SUM(N8:N142) -> 2.204681e+10

Sheet JULIO
A3: TRANSFERENCIAS DE FONDOS
A4: MES DE JULIO 2021
N5: (En pesos)
A6: Municipio | B6: JULIO 2021
B7: Coparticipación Bruta | C7: Omisión Coparticiación 2020 | D7: Descentralización | E7: Juegos de Azar | F7: F.F.P.S. (Programas Sociales) | G7: F.S.A. (Tratamiento de Residuos) | H7: Fondo Fort. Recursos Municipales | I7: Fondo Inclusión Social | J7: Fondo de Financ. Educativo | K7: Fdo. Para Infrestructura Municipal 2016 | L7: Fdo. Para Infrestructura Municipal 2017 | M7: Fdo Ley 14890 | N7: Total
A8: ADOLFO ALSINA | B8: 68435582 | C8: 0 | D8: 16723771 | E8: 0 | F8: 228809.92 | G8: 119143.39 | H8: 3783262.7 | I8: 585523.09 | J8: 5840288.2 | K8: 0 | L8: 0 | M8: 743.12 | N8: =SUM(B8:M8) -> 95717123
A9: ADOLFO GONZALES CHAVES | B9: 42665270 | C9: 0 | D9: 15445975 | E9: 0 | F9: 160309.06 | G9: 84165.51 | H9: 2358625.7 | I9: 410229.84 | J9: 4383370.1 | K9: 0 | L9: 0 | M9: 520.64 | N9: =SUM(B9:M9) -> 65508466
A10: ALBERTI | B10: 31355393 | C10: 0 | D10: 11632052 | E10: 0 | F10: 111988.95 | G10: 74327.99 | H10: 1733392 | I10: 286579 | J10: 2590874 | K10: 0 | L10: 0 | M10: 363.69 | N10: =SUM(B10:M10) -> 47784971
A11: ALMIRANTE BROWN | B11: 3.6309839e+08 | C11: 0 | D11: 4296680.8 | E11: 0 | F11: 12020337 | G11: 6776705.9 | H11: 20072841 | I11: 30759965 | J11: 48761921 | K11: 0 | L11: 0 | M11: 39040.95 | N11: =SUM(B11:M11) -> 4.8582588e+08
A12: ARRECIFES | B12: 54499075 | C12: 0 | D12: 14452447 | E12: 0 | F12: 411005.14 | G12: 203308.9 | H12: 3012823.3 | I12: 1051759.5 | J12: 5260190.5 | K12: 0 | L12: 0 | M12: 1334.86 | N12: =SUM(B12:M12) -> 78891944
A13: AVELLANEDA | B13: 2.2033652e+08 | C13: 0 | D13: 5153270.1 | E13: 0 | F13: 5845311.8 | G13: 1778656.2 | H13: 12180665 | I13: 14958115 | J13: 37491776 | K13: 0 | L13: 0 | M13: 18985.02 | N13: =SUM(B13:M13) -> 2.977633e+08
A14: AYACUCHO | B14: 79851991 | C14: 0 | D14: 25749903 | E14: 0 | F14: 266044.82 | G14: 142097.62 | H14: 4414385.7 | I14: 680806.97 | J14: 7545827.3 | K14: 0 | L14: 0 | M14: 864.03 | N14: =SUM(B14:M14) -> 1.1865192e+08
A15: AZUL | B15: 1.3013519e+08 | C15: 0 | D15: 37575681 | E15: 0 | F15: 991130.67 | G15: 456898.5 | H15: 7194146.3 | I15: 2536296.9 | J15: 12598706 | K15: 0 | L15: 0 | M15: 3219.07 | N15: =SUM(B15:M15) -> 1.9149126e+08
A16: BAHIA BLANCA | B16: 2.4054271e+08 | C16: 0 | D16: 9204387.9 | E16: 0 | F16: 3696488.2 | G16: 2109603.1 | H16: 13297706 | I16: 9459289.2 | J16: 31231810 | K16: 0 | L16: 0 | M16: 12005.83 | N16: =SUM(B16:M16) -> 3.09554e+08
A17: BALCARCE | B17: 86430790 | C17: 0 | D17: 34968299 | E17: 0 | F17: 759194.15 | G17: 306056.41 | H17: 4778075.6 | I17: 1942772.9 | J17: 8613407.5 | K17: 0 | L17: 0 | M17: 2465.75 | N17: =SUM(B17:M17) -> 1.3780106e+08
A18: BARADERO | B18: 52990160 | C18: 0 | D18: 11256896 | E18: 0 | F18: 511624.66 | G18: 229542.31 | H18: 2929407.3 | I18: 1309244.2 | J18: 6954908.1 | K18: 0 | L18: 0 | M18: 1661.66 | N18: =SUM(B18:M18) -> 76183445
A19: BENITO JUAREZ | B19: 88647009 | C19: 0 | D19: 22181617 | E19: 0 | F19: 206639.51 | G19: 142097.62 | H19: 4900592.8 | I19: 528789.18 | J19: 5908934.4 | K19: 0 | L19: 0 | M19: 671.11 | N19: =SUM(B19:M19) -> 1.2251635e+08
... A142: ZARATE | B142: 98180767 | C142: 0 | D142: 12764856 | E142: 0 | F142: 2706778.7 | G142: 799025.85 | H142: 5427639 | I142: 6926629 | J142: 14816538 | K142: 0 | L142: 0 | M142: 8791.33 | N142: =SUM(B142:M142) -> 1.4163103e+08
A143: CONSOLIDADO 135 MUNICIPIOS | B143: =SUM(B8:B142) -> 1.7464294e+10 | C143: =SUM(C8:C142) -> 0 | D143: =SUM(D8:D142) -> 1.6043853e+09 | E143: =SUM(E8:E142) -> 0 | F143: =SUM(F8:F142) -> 2.8423593e+08 | G143: =SUM(G8:G142) -> 1.0930586e+08 | H143: =SUM(H8:H142) -> 9.6546284e+08 | I143: =SUM(I8:I142) -> 7.2735788e+08 | ... N143: =SUM(N8:N142) -> 2.2987023e+10

Sheet AGOSTO
A3: TRANSFERENCIAS DE FONDOS
A4: MES DE AGOSTO 2021
N5: (En pesos)
A6: Municipio | B6: AGOSTO 2021
B7: Coparticipación Bruta | C7: Omisión Coparticiación 2020 | D7: Descentralización | E7: Juegos de Azar | F7: F.F.P.S. (Programas Sociales) | G7: F.S.A. (Tratamiento de Residuos) | H7: Fondo Fort. Recursos Municipales | I7: Fondo Inclusión Social | J7: Fondo de Financ. Educativo | K7: Fdo. Para Infrestructura Municipal 2016 | L7: Fdo. Para Infrestructura Municipal 2017 | M7: Fdo Ley 14890 | N7: Total
A8: ADOLFO ALSINA | B8: 69540033 | C8: 0 | D8: 2947090 | E8: 0 | F8: 216473.78 | G8: 118024.76 | H8: 3930622.7 | I8: 608099.19 | J8: 5840288.2 | K8: 0 | L8: 0 | M8: 432.55 | N8: =SUM(B8:M8) -> 83201064
A9: ADOLFO GONZALES CHAVES | B9: 43353826 | C9: 0 | D9: 1812314.1 | E9: 0 | F9: 151666.1 | G9: 83375.29 | H9: 2450495.4 | I9: 426047.14 | J9: 4383370.1 | K9: 0 | L9: 0 | M9: 303.04 | N9: =SUM(B9:M9) -> 52661397
A10: ALBERTI | B10: 31861424 | C10: 0 | D10: 1044150.5 | E10: 0 | F10: 105951.14 | G10: 73630.13 | H10: 1800908.5 | I10: 297628.67 | J10: 2590874 | K10: 0 | L10: 0 | M10: 211.69 | N10: =SUM(B10:M10) -> 37774778
A11: ALMIRANTE BROWN | B11: 3.6895827e+08 | C11: 0 | D11: 3138036.6 | E11: 0 | F11: 11372269 | G11: 6687063.1 | H11: 20854689 | I11: 31945981 | J11: 48761921 | K11: 0 | L11: 0 | M11: 22726.01 | N11: =SUM(B11:M11) -> 4.9174096e+08
A12: ARRECIFES | B12: 55378612 | C12: 0 | D12: 1959057.2 | E12: 0 | F12: 388846.08 | G12: 201400.05 | H12: 3130174.4 | I12: 1092312.3 | J12: 5260190.5 | K12: 0 | L12: 0 | M12: 777.02 | N12: =SUM(B12:M12) -> 67411369
A13: AVELLANEDA | B13: 2.2389243e+08 | C13: 0 | D13: 2817900.3 | E13: 0 | F13: 5530165.8 | G13: 1694514.2 | H13: 12655109 | I13: 15534857 | J13: 37491776 | K13: 0 | L13: 0 | M13: 11051.29 | N13: =SUM(B13:M13) -> 2.996278e+08
A14: AYACUCHO | B14: 81140686 | C14: 0 | D14: 3634381.9 | E14: 0 | F14: 251701.2 | G14: 140763.48 | H14: 4586328.3 | I14: 707056.95 | J14: 7545827.3 | K14: 0 | L14: 0 | M14: 502.95 | N14: =SUM(B14:M14) -> 98007249
A15: AZUL | B15: 1.3223538e+08 | C15: 0 | D15: 4309232.2 | E15: 0 | F15: 937694.54 | G15: 452608.72 | H15: 7474362.1 | I15: 2634089.3 | J15: 12598706 | K15: 0 | L15: 0 | M15: 1873.82 | N15: =SUM(B15:M15) -> 1.6064395e+08
A16: BAHIA BLANCA | B16: 2.4442472e+08 | C16: 0 | D16: 6394940.6 | E16: 0 | F16: 3497194.6 | G16: 2089796.2 | H16: 13815658 | I16: 9824012.4 | J16: 31231810 | K16: 0 | L16: 0 | M16: 6988.65 | N16: =SUM(B16:M16) -> 3.1128512e+08
A17: BALCARCE | B17: 87825658 | C17: 0 | D17: 4574170.2 | E17: 0 | F17: 718262.72 | G17: 303182.87 | H17: 4964184.1 | I17: 2017680.7 | J17: 8613407.5 | K17: 0 | L17: 0 | M17: 1435.31 | N17: =SUM(B17:M17) -> 1.0901798e+08
A18: BARADERO | B18: 53845345 | C18: 0 | D18: 1519998.1 | E18: 0 | F18: 484040.77 | G18: 227387.16 | H18: 3043509.3 | I18: 1359724.9 | J18: 6954908.1 | K18: 0 | L18: 0 | M18: 967.25 | N18: =SUM(B18:M18) -> 67435881
A19: BENITO JUAREZ | B19: 90077644 | C19: 0 | D19: 2865773.2 | E19: 0 | F19: 195498.68 | G19: 140763.48 | H19: 5091473.5 | I19: 549177.78 | J19: 5908934.4 | K19: 0 | L19: 0 | M19: 390.63 | N19: =SUM(B19:M19) -> 1.0482966e+08
... A142: ZARATE | B142: 99765263 | C142: 0 | D142: 1594441.1 | E142: 0 | F142: 2560844.6 | G142: 791523.86 | H142: 5639048.3 | I142: 7193700.1 | J142: 14816538 | K142: 0 | L142: 0 | M142: 5117.48 | N142: =SUM(B142:M142) -> 1.3236648e+08
A143: CONSOLIDADO 135 MUNICIPIOS | B143: =SUM(B8:B142) -> 1.7746142e+10 | C143: =SUM(C8:C142) -> 0 | D143: =SUM(D8:D142) -> 3.3970741e+08 | E143: =SUM(E8:E142) -> 0 | F143: =SUM(F8:F142) -> 2.6891154e+08 | G143: =SUM(G8:G142) -> 1.082796e+08 | H143: =SUM(H8:H142) -> 1.0030681e+09 | I143: =SUM(I8:I142) -> 7.5540272e+08 | ... N143: =SUM(N8:N142) -> 2.2053107e+10

Sheet SEPTIEMBRE
A3: TRANSFERENCIAS DE FONDOS
A4: MES DE SEPTIEMBRE 2021
N5: (En pesos)
A6: Municipio | B6: SEPTIEMBRE 2021
B7: Coparticipación Bruta | C7: Omisión Coparticiación 2020 | D7: Descentralización | E7: Juegos de Azar | F7: F.F.P.S. (Programas Sociales) | G7: F.S.A. (Tratamiento de Residuos) | H7: Fondo Fort. Recursos Municipales | I7: Fondo Inclusión Social | J7: Fondo de Financ. Educativo | K7: Fdo. Para Infrestructura Municipal 2016 | L7: Fdo. Para Infrestructura Municipal 2017 | M7: Fdo Ley 14890 | N7: Total
A8: ADOLFO ALSINA | B8: 71093911 | C8: 0 | D8: 3121703.1 | E8: 0 | F8: 353505.34 | G8: 173745.56 | H8: 3629286.4 | I8: 561908.23 | J8: 6118397.1 | K8: 0 | L8: 0 | M8: 163.29 | N8: =SUM(B8:M8) -> 85052620
A9: ADOLFO GONZALES CHAVES | B9: 44322570 | C9: 0 | D9: 2027129.2 | E9: 0 | F9: 247673.31 | G9: 122737.69 | H9: 2262631.2 | I9: 393684.77 | J9: 4592102 | K9: 0 | L9: 0 | M9: 114.4 | N9: =SUM(B9:M9) -> 53968643
A10: ALBERTI | B10: 32573370 | C10: 0 | D10: 1454683.8 | E10: 0 | F10: 173020 | G10: 108391.72 | H10: 1662844.1 | I10: 275020.92 | J10: 2714248.9 | K10: 0 | L10: 0 | M10: 79.91 | N10: =SUM(B10:M10) -> 38961659
A11: ALMIRANTE BROWN | B11: 3.7720267e+08 | C11: 0 | D11: 3591661 | E11: 0 | F11: 18571107 | G11: 9632484.3 | H11: 19255890 | I11: 29519378 | J11: 51083918 | K11: 0 | L11: 0 | M11: 8579.72 | N11: =SUM(B11:M11) -> 5.0886569e+08
A12: ARRECIFES | B12: 56616051 | C12: 0 | D12: 1562347.1 | E12: 0 | F12: 634992.21 | G12: 296483.24 | H12: 2890203.4 | I12: 1009340.8 | J12: 5510675.7 | K12: 0 | L12: 0 | M12: 293.33 | N12: =SUM(B12:M12) -> 68520387
A13: AVELLANEDA | B13: 2.2889533e+08 | C13: 0 | D13: 3378802.7 | E13: 0 | F13: 9030854 | G13: 2862564.4 | H13: 11684920 | I13: 14354836 | J13: 39277099 | K13: 0 | L13: 0 | M13: 4172.18 | N13: =SUM(B13:M13) -> 3.0948857e+08
A14: AYACUCHO | B14: 82953782 | C14: 0 | D14: 3904152.5 | E14: 0 | F14: 411032.3 | G14: 207219.47 | H14: 4234723.1 | I14: 653349.2 | J14: 7905152.4 | K14: 0 | L14: 0 | M14: 189.87 | N14: =SUM(B14:M14) -> 1.002696e+08
A15: AZUL | B15: 1.3519019e+08 | C15: 0 | D15: 4602161 | E15: 0 | F15: 1531271 | G15: 666290.3 | H15: 6901349.3 | I15: 2434005 | J15: 13198644 | K15: 0 | L15: 0 | M15: 707.42 | N15: =SUM(B15:M15) -> 1.6452462e+08
A16: BAHIA BLANCA | B16: 2.4988641e+08 | C16: 0 | D16: 6883906.6 | E16: 0 | F16: 5710977.7 | G16: 3076412.2 | H16: 12756498 | I16: 9077784.5 | J16: 32719039 | K16: 0 | L16: 0 | M16: 2638.41 | N16: =SUM(B16:M16) -> 3.2011366e+08
A17: BALCARCE | B17: 89788130 | C17: 0 | D17: 4881985 | E17: 0 | F17: 1172935.1 | G17: 446318.86 | H17: 4583611 | I17: 1864418.5 | J17: 9023569.7 | K17: 0 | L17: 0 | M17: 541.86 | N17: =SUM(B17:M17) -> 1.1176151e+08
A18: BARADERO | B18: 55048524 | C18: 0 | D18: 1521813.8 | E18: 0 | F18: 790446.73 | G18: 334739.15 | H18: 2810182.4 | I18: 1256440.8 | J18: 7286094.2 | K18: 0 | L18: 0 | M18: 365.15 | N18: =SUM(B18:M18) -> 69048606
A19: BENITO JUAREZ | B19: 92090436 | C19: 0 | D19: 3053461.9 | E19: 0 | F19: 319252.65 | G19: 207219.47 | H19: 4701141.9 | I19: 507462.46 | J19: 6190312.3 | K19: 0 | L19: 0 | M19: 147.47 | N19: =SUM(B19:M19) -> 1.0706943e+08
... A142: ZARATE | B142: 1.0199453e+08 | C142: 0 | D142: 2030147.4 | E142: 0 | F142: 4181902.4 | G142: 1165211 | H142: 5206737.6 | I142: 6647269.7 | J142: 15522087 | K142: 0 | L142: 0 | M142: 1931.99 | N142: =SUM(B142:M142) -> 1.3674981e+08
A143: CONSOLIDADO 135 MUNICIPIOS | B143: =SUM(B8:B142) -> 1.8142681e+10 | C143: =SUM(C8:C142) -> 0 | D143: =SUM(D8:D142) -> 3.6530171e+08 | E143: =SUM(E8:E142) -> 0 | F143: =SUM(F8:F142) -> 4.3913708e+08 | G143: =SUM(G8:G142) -> 1.5939959e+08 | H143: =SUM(H8:H142) -> 9.2616914e+08 | I143: =SUM(I8:I142) -> 6.9802265e+08 | ... N143: =SUM(N8:N142) -> 2.2649166e+10

Sheet OCTUBRE
A3: TRANSFERENCIAS DE FONDOS
A4: MES DE OCTUBRE 2021
N5: (En pesos)
A6: Municipio | B6: OCTUBRE 2021
B7: Coparticipación Bruta | C7: Omisión Coparticiación 2020 | D7: Descentralización | E7: Juegos de Azar | F7: F.F.P.S. (Programas Sociales) | G7: F.S.A. (Tratamiento de Residuos) | H7: Fondo Fort. Recursos Municipales | I7: Fondo Inclusión Social | J7: Fondo de Financ. Educativo | K7: Fdo. Para Infrestructura Municipal 2016 | L7: Fdo. Para Infrestructura Municipal 2017 | M7: Fdo Ley 14890 | N7: Total
A8: ADOLFO ALSINA | B8: 74991444 | D8: 16203923 | F8: 284165.49 | G8: 154609.77 | H8: 3720159.6 | I8: 576033.34 | J8: 5284070.2 | M8: 176.29 | N8: =SUM(B8:M8) -> 1.0121458e+08
A9: ADOLFO GONZALES CHAVES | B9: 46752437 | D9: 14265952 | F9: 199092.34 | G9: 109219.75 | H9: 2319284.9 | I9: 403581.12 | J9: 3965906.3 | M9: 123.52 | N9: =SUM(B9:M9) -> 68015596
A10: ALBERTI | B10: 34359118 | D10: 11923663 | F10: 139082.24 | G10: 96453.8 | H10: 1704479.8 | I10: 281934.33 | J10: 2344124 | M10: 86.29 | N10: =SUM(B10:M10) -> 50848941
A11: ALMIRANTE BROWN | B11: 3.978818e+08 | D11: 5486819.1 | F11: 14928396 | G11: 8506983.8 | H11: 19738035 | I11: 30261428 | J11: 44117929 | M11: 9262.59 | N11: =SUM(B11:M11) -> 5.2093065e+08
A12: ARRECIFES | B12: 59719875 | D12: 14988578 | F12: 510438.89 | G12: 263829.52 | H12: 2962570.8 | I12: 1034713.3 | J12: 4759219.9 | M12: 316.69 | N12: =SUM(B12:M12) -> 84239542
A13: AVELLANEDA | B13: 2.414439e+08 | D13: 4013585.6 | F13: 7259457.7 | G13: 2428568.9 | H13: 11977497 | I13: 14715684 | J13: 33921131 | M13: 4504.25 | N13: =SUM(B13:M13) -> 3.1576433e+08
A14: AYACUCHO | B14: 87501501 | D14: 23736018 | F14: 330408.57 | G14: 184396.98 | H14: 4340755.8 | I14: 669772.92 | J14: 6827177.1 | M14: 204.98 | N14: =SUM(B14:M14) -> 1.2359024e+08
A15: AZUL | B15: 1.4260163e+08 | D15: 38374406 | F15: 1230913.1 | G15: 592907.2 | H15: 7074151.2 | I15: 2495190.4 | J15: 11398829 | M15: 763.73 | N15: =SUM(B15:M15) -> 2.0376879e+08
A16: BAHIA BLANCA | B16: 2.6358576e+08 | D16: 11794942 | F16: 4590773 | G16: 2737585.9 | H16: 13075906 | I16: 9305979.5 | J16: 28257352 | M16: 2848.42 | N16: =SUM(B16:M16) -> 3.3335115e+08
A17: BALCARCE | B17: 94710524 | D17: 34984181 | F17: 942864.64 | G17: 397162.72 | H17: 4698379.4 | I17: 1911285.8 | J17: 7793082.9 | M17: 585.01 | N17: =SUM(B17:M17) -> 1.4543807e+08
A18: BARADERO | B18: 58066412 | D18: 12180965 | F18: 635401.1 | G18: 297872.04 | H18: 2880546.1 | I18: 1288024.9 | J18: 6292535.9 | M18: 394.23 | N18: =SUM(B18:M18) -> 81642151
A19: BENITO JUAREZ | B19: 97139048 | D19: 22528680 | F19: 256631.44 | G19: 184396.98 | H19: 4818853.1 | I19: 520218.93 | J19: 5346178.8 | M19: 159.21 | N19: =SUM(B19:M19) -> 1.3079417e+08
... A142: ZARATE | B142: 1.075861e+08 | D142: 10638113 | F142: 3361624.9 | G142: 1036878.4 | H142: 5337108.4 | I142: 6814367 | J142: 13405439 | M142: 2085.76 | N142: =SUM(B142:M142) -> 1.4818172e+08
A143: CONSOLIDADO 135 MUNICIPIOS | B143: =SUM(B8:B142) -> 1.9137305e+10 | D143: =SUM(D8:D142) -> 1.6268137e+09 | E143: =SUM(E8:E142) -> 0 | F143: =SUM(F8:F142) -> 3.5300062e+08 | G143: =SUM(G8:G142) -> 1.4184383e+08 | H143: =SUM(H8:H142) -> 9.4935935e+08 | I143: =SUM(I8:I142) -> 7.1556936e+08 | J143: =SUM(J8:J142) -> 1.6566717e+09 | K143: =SUM(K8:K142) -> 0 | ... N143: =SUM(N8:N142) -> 2.4580783e+10

Sheet NOVIEMBRE
A3: TRANSFERENCIAS DE FONDOS
A4: MES DE NOVIEMBRE 2021
N5: (En pesos)
A6: Municipio | B6: NOVIEMBRE 2021
B7: Coparticipación Bruta | C7: Omisión Coparticiación 2020 | D7: Descentralización | E7: Juegos de Azar | F7: F.F.P.S. (Programas Sociales) | G7: F.S.A. (Tratamiento de Residuos) | H7: Fondo Fort. Recursos Municipales | I7: Fondo Inclusión Social | J7: Fondo de Financ. Educativo | K7: Fdo. Para Infrestructura Municipal 2016 | L7: Fdo. Para Infrestructura Municipal 2017 | M7: Fdo Ley 14890 | N7: Total
A8: ADOLFO ALSINA | B8: 77578866 | C8: 0 | D8: 2621730.4 | E8: 0 | F8: 349493.86 | G8: 170532.88 | H8: 4274785.7 | I8: 661618.76 | J8: 5840288.2 | K8: 0 | L8: 0 | M8: 201.15 | N8: =SUM(B8:M8) -> 91497517
A9: ADOLFO GONZALES CHAVES | B9: 48365531 | C9: 0 | D9: 1802993.7 | E9: 0 | F9: 244862.78 | G9: 120468.18 | H9: 2665059.3 | I9: 463544.08 | J9: 4383370.1 | K9: 0 | L9: 0 | M9: 140.94 | N9: =SUM(B9:M9) -> 58045970
A10: ALBERTI | B10: 35544607 | C10: 0 | D10: 1017230.2 | E10: 0 | F10: 171056.62 | G10: 106387.48 | H10: 1958595 | I10: 323823.34 | J10: 2590874 | K10: 0 | L10: 0 | M10: 98.44 | N10: =SUM(B10:M10) -> 41712672
A11: ALMIRANTE BROWN | B11: 4.1160987e+08 | C11: 0 | D11: 3932527.8 | E11: 0 | F11: 18360367 | G11: 9395195.1 | H11: 22680713 | I11: 34757587 | J11: 48761921 | K11: 0 | L11: 0 | M11: 10569.02 | N11: =SUM(B11:M11) -> 5.4950875e+08
A12: ARRECIFES | B12: 61780383 | C12: 0 | D12: 1746629.8 | E12: 0 | F12: 627786.49 | G12: 291001.06 | H12: 3404250.5 | I12: 1188448.1 | J12: 5260190.5 | K12: 0 | L12: 0 | M12: 361.36 | N12: =SUM(B12:M12) -> 74299051
A13: AVELLANEDA | B13: 2.4977441e+08 | C13: 0 | D13: 3376433.2 | E13: 0 | F13: 8928374.3 | G13: 2792259.8 | H13: 13763182 | I13: 16902099 | J13: 37491776 | K13: 0 | L13: 0 | M13: 5139.54 | N13: =SUM(B13:M13) -> 3.3303368e+08
A14: AYACUCHO | B14: 90520556 | C14: 0 | D14: 3124213.2 | E14: 0 | F14: 406368.02 | G14: 203387.84 | H14: 4987904.5 | I14: 769285.91 | J14: 7545827.3 | K14: 0 | L14: 0 | M14: 233.9 | N14: =SUM(B14:M14) -> 1.0755778e+08
A15: AZUL | B15: 1.475218e+08 | C15: 0 | D15: 4240248.5 | E15: 0 | F15: 1513894.5 | G15: 653970.12 | H15: 8128812.7 | I15: 2865918.8 | J15: 12598706 | K15: 0 | L15: 0 | M15: 871.43 | N15: =SUM(B15:M15) -> 1.7752422e+08
A16: BAHIA BLANCA | B16: 2.7268023e+08 | C16: 0 | D16: 7877693.5 | E16: 0 | F16: 5646171.1 | G16: 3019527.1 | H16: 15025349 | I16: 10688636 | J16: 31231810 | K16: 0 | L16: 0 | M16: 3250.16 | N16: =SUM(B16:M16) -> 3.4617267e+08
A17: BALCARCE | B17: 97978311 | C17: 0 | D17: 4017979.6 | E17: 0 | F17: 1159625 | G17: 438066.11 | H17: 5398845.1 | I17: 2195259.3 | J17: 8613407.5 | K17: 0 | L17: 0 | M17: 667.5 | N17: =SUM(B17:M17) -> 1.1980216e+08
A18: BARADERO | B18: 60069871 | C18: 0 | D18: 1744396 | E18: 0 | F18: 781476.96 | G18: 328549.58 | H18: 3309997.1 | I18: 1479396 | J18: 6954908.1 | K18: 0 | L18: 0 | M18: 449.84 | N18: =SUM(B18:M18) -> 74669044
A19: BENITO JUAREZ | B19: 1.0049063e+08 | C19: 0 | D19: 2662032.3 | E19: 0 | F19: 315629.86 | G19: 203387.84 | H19: 5537279.8 | I19: 597511.6 | J19: 5908934.4 | K19: 0 | L19: 0 | M19: 181.67 | N19: =SUM(B19:M19) -> 1.1571558e+08
... A142: ZARATE | B142: 1.1129813e+08 | C142: 0 | D142: 1787106.4 | E142: 0 | F142: 4134447.3 | G142: 1143665.4 | H142: 6132800 | I142: 7826826.7 | J142: 14816538 | K142: 0 | L142: 0 | M142: 2379.95 | N142: =SUM(B142:M142) -> 1.471419e+08
A143: CONSOLIDADO 135 MUNICIPIOS | B143: =SUM(B8:B142) -> 1.9797598e+10 | D143: =SUM(D8:D142) -> 3.5716355e+08 | E143: =SUM(E8:E142) -> 0 | F143: =SUM(F8:F142) -> 4.3415387e+08 | G143: =SUM(G8:G142) -> 1.5645218e+08 | H143: =SUM(H8:H142) -> 1.0908962e+09 | I143: =SUM(I8:I142) -> 8.2188666e+08 | J143: =SUM(J8:J142) -> 1.8310582e+09 | K143: =SUM(K8:K142) -> 0 | ... N143: =SUM(N8:N142) -> 2.4489458e+10

Sheet DICIEMBRE
A3: TRANSFERENCIAS DE FONDOS
A4: MES DE DICIEMBRE 2021
N5: (En pesos)
A6: Municipio | B6: DICIEMBRE 2021
B7: Coparticipación Bruta | C7: Omisión Coparticiación 2020 | D7: Descentralización | E7: Juegos de Azar | F7: F.F.P.S. (Programas Sociales) | G7: F.S.A. (Tratamiento de Residuos) | H7: Fondo Fort. Recursos Municipales | I7: Fondo Inclusión Social | J7: Fondo de Financ. Educativo | K7: Fdo. Para Infrestructura Municipal 2016 | L7: Fdo. Para Infrestructura Municipal 2017 | M7: Fdo Ley 14890 | N7: Total
A8: ADOLFO ALSINA | B8: 85021987 | C8: 0 | D8: 16815376 | E8: 0 | F8: 261829.58 | G8: 144785.25 | H8: 5021553.7 | I8: 778743.89 | J8: 6118397.1 | K8: 0 | L8: 0 | M8: 162.35 | N8: =SUM(B8:M8) -> 1.1416284e+08
A9: ADOLFO GONZALES CHAVES | B9: 53005848 | C9: 0 | D9: 14493029 | E9: 0 | F9: 183443.33 | G9: 102279.49 | H9: 3130622.1 | I9: 545604.42 | J9: 4592102 | K9: 0 | L9: 0 | M9: 113.73 | N9: =SUM(B9:M9) -> 76053041
A10: ALBERTI | B10: 38954850 | C10: 0 | D10: 11868099 | E10: 0 | F10: 128150.13 | G10: 90324.75 | H10: 2300744.5 | I10: 381149.18 | J10: 2714248.9 | K10: 0 | L10: 0 | M10: 79.45 | N10: =SUM(B10:M10) -> 56437646
A11: ALMIRANTE BROWN | B11: 4.5110081e+08 | C11: 0 | D11: 5371947.2 | E11: 0 | F11: 13754998 | G11: 8337091.7 | H11: 26642837 | I11: 40910657 | J11: 51083918 | K11: 0 | L11: 0 | M11: 8529.77 | N11: =SUM(B11:M11) -> 5.9721079e+08
A12: ARRECIFES | B12: 67707756 | C12: 0 | D12: 15075965 | E12: 0 | F12: 470317.49 | G12: 247064.74 | H12: 3998943.6 | I12: 1398836.9 | J12: 5510675.7 | K12: 0 | L12: 0 | M12: 291.62 | N12: =SUM(B12:M12) -> 94409851
A13: AVELLANEDA | B13: 2.7373843e+08 | C13: 0 | D13: 3785328.1 | E13: 0 | F13: 6688851.5 | G13: 0 | H13: 16167491 | I13: 19894246 | J13: 39277099 | K13: 0 | L13: 0 | M13: 4147.88 | N13: =SUM(B13:M13) -> 3.5955559e+08
A14: AYACUCHO | B14: 99205337 | C14: 0 | D14: 24797051 | E14: 0 | F14: 304437.88 | G14: 172679.66 | H14: 5859248.2 | I14: 905471.16 | J14: 7905152.4 | K14: 0 | L14: 0 | M14: 188.77 | N14: =SUM(B14:M14) -> 1.3914957e+08
A15: AZUL | B15: 1.6167543e+08 | C15: 0 | D15: 38739579 | E15: 0 | F15: 1134161.2 | G15: 555231.52 | H15: 9548845.9 | I15: 3373267 | J15: 13198644 | K15: 0 | L15: 0 | M15: 703.3 | N15: =SUM(B15:M15) -> 2.2822586e+08
A16: BAHIA BLANCA | B16: 2.9884189e+08 | C16: 0 | D16: 10892154 | E16: 0 | F16: 4229930.2 | G16: 2563628.8 | H16: 17650148 | I16: 12580825 | J16: 32719039 | K16: 0 | L16: 0 | M16: 2623.06 | N16: =SUM(B16:M16) -> 3.7948024e+08
A17: BALCARCE | B17: 1.0737861e+08 | C17: 0 | D17: 34163461 | E17: 0 | F17: 868753.82 | G17: 371925.42 | H17: 6341976.6 | I17: 2583881.9 | J17: 9023569.7 | K17: 0 | L17: 0 | M17: 538.72 | N17: =SUM(B17:M17) -> 1.6073272e+08
A18: BARADERO | B18: 65833133 | C18: 0 | D18: 13852672 | E18: 0 | F18: 585457.46 | G18: 278944.07 | H18: 3888225 | I18: 1741290.7 | J18: 7286094.2 | K18: 0 | L18: 0 | M18: 363.03 | N18: =SUM(B18:M18) -> 93466179
A19: BENITO JUAREZ | B19: 1.1013196e+08 | C19: 0 | D19: 23314180 | E19: 0 | F19: 236459.76 | G19: 172679.66 | H19: 6504594.6 | I19: 703287.96 | J19: 6190312.3 | K19: 0 | L19: 0 | M19: 146.6 | N19: =SUM(B19:M19) -> 1.4725362e+08
... A142: ZARATE | B142: 1.2197637e+08 | C142: 0 | D142: 10750805 | E142: 0 | F142: 3097395.2 | G142: 970991.01 | H142: 7204147.1 | I142: 9212395.2 | J142: 15522087 | K142: 0 | L142: 0 | M142: 1920.75 | N142: =SUM(B142:M142) -> 1.6873611e+08
A143: CONSOLIDADO 135 MUNICIPIOS | B143: =SUM(B8:B142) -> 2.1697031e+10 | C143: =SUM(C8:C142) -> 0 | D143: =SUM(D8:D142) -> 1.6358203e+09 | E143: =SUM(E8:E142) -> 0 | F143: =SUM(F8:F142) -> 3.2525415e+08 | G143: =SUM(G8:G142) -> 1.3283051e+08 | H143: =SUM(H8:H142) -> 1.2814663e+09 | I143: =SUM(I8:I142) -> 9.6738372e+08 | ... N143: =SUM(N8:N142) -> 2.7958239e+10

Sheet Acumulado
A3: TRANSFERENCIAS DE FONDOS
A4: ACUMULADO ENERO - DICIEMBRE 2021
N5: (En pesos)
A6: Municipio | B6: Acumulado ENERO - DICIEMBRE 2021
B7: Coparticipación Bruta | C7: Omisión Coparticiación 2020 | D7: Descentralización | E7: Juegos de Azar | F7: F.F.P.S. (Programas Sociales) | G7: F.S.A. (Tratamiento de Residuos) | H7: Fondo Fort. Recursos Municipales | I7: Fondo Inclusión Social | J7: Fondo de Financ. Educativo | K7: Fdo. Para Infrestructura Municipal 2016 | L7: Fdo. Para Infrestructura Municipal 2017 | M7: Fdo Ley 14890 | N7: Total
A8: ADOLFO ALSINA | B8: =ENERO!B8+FEBRERO!B8+MARZO!B8+ABRIL!B8+MAYO!B8+JUNIO!B8+JULIO!B8+AGOSTO!B8+SEPTIEMBRE!B8+OCTUBRE!B8+NOVIEMBRE!B8+DICIEMBRE!B8 -> 8.1091808e+08 | C8: =ENERO!C8+FEBRERO!C8+MARZO!C8+ABRIL!C8+MAYO!C8+JUNIO!C8+JULIO!C8+AGOSTO!C8+SEPTIEMBRE!C8+OCTUBRE!C8+NOVIEMBRE!C8+DICIEMBRE!C8 -> 0 | D8: =ENERO!D8+FEBRERO!D8+MARZO!D8+ABRIL!D8+MAYO!D8+JUNIO!D8+JULIO!D8+AGOSTO!D8+SEPTIEMBRE!D8+OCTUBRE!D8+NOVIEMBRE!D8+DICIEMBRE!D8 -> 85766087 | E8: =ENERO!E8+FEBRERO!E8+MARZO!E8+ABRIL!E8+MAYO!E8+JUNIO!E8+JULIO!E8+AGOSTO!E8+SEPTIEMBRE!E8+OCTUBRE!E8+NOVIEMBRE!E8+DICIEMBRE!E8 -> 474630.95 | F8: =ENERO!F8+FEBRERO!F8+MARZO!F8+ABRIL!F8+MAYO!F8+JUNIO!F8+JULIO!F8+AGOSTO!F8+SEPTIEMBRE!F8+OCTUBRE!F8+NOVIEMBRE!F8+DICIEMBRE!F8 -> 2885147.6 | G8: =ENERO!G8+FEBRERO!G8+MARZO!G8+ABRIL!G8+MAYO!G8+JUNIO!G8+JULIO!G8+AGOSTO!G8+SEPTIEMBRE!G8+OCTUBRE!G8+NOVIEMBRE!G8+DICIEMBRE!G8 -> 1482262.4 | H8: =ENERO!H8+FEBRERO!H8+MARZO!H8+ABRIL!H8+MAYO!H8+JUNIO!H8+JULIO!H8+AGOSTO!H8+SEPTIEMBRE!H8+OCTUBRE!H8+NOVIEMBRE!H8+DICIEMBRE!H8 -> 43054477 | I8: =ENERO!I8+FEBRERO!I8+MARZO!I8+ABRIL!I8+MAYO!I8+JUNIO!I8+JULIO!I8+AGOSTO!I8+SEPTIEMBRE!I8+OCTUBRE!I8+NOVIEMBRE!I8+DICIEMBRE!I8 -> 6669207.2 | ... M8: =ENERO!M8+FEBRERO!M8+MARZO!M8+ABRIL!M8+MAYO!M8+JUNIO!M8+JULIO!M8+AGOSTO!M8+SEPTIEMBRE!M8+OCTUBRE!M8+NOVIEMBRE!M8+DICIEMBRE!M8 -> 22140.74 | N8: =SUM(B8:M8) -> 1.0196868e+09
A9: ADOLFO GONZALES CHAVES | B9: =ENERO!B9+FEBRERO!B9+MARZO!B9+ABRIL!B9+MAYO!B9+JUNIO!B9+JULIO!B9+AGOSTO!B9+SEPTIEMBRE!B9+OCTUBRE!B9+NOVIEMBRE!B9+DICIEMBRE!B9 -> 5.0555629e+08 | C9: =ENERO!C9+FEBRERO!C9+MARZO!C9+ABRIL!C9+MAYO!C9+JUNIO!C9+JULIO!C9+AGOSTO!C9+SEPTIEMBRE!C9+OCTUBRE!C9+NOVIEMBRE!C9+DICIEMBRE!C9 -> 0 | D9: =ENERO!D9+FEBRERO!D9+MARZO!D9+ABRIL!D9+MAYO!D9+JUNIO!D9+JULIO!D9+AGOSTO!D9+SEPTIEMBRE!D9+OCTUBRE!D9+NOVIEMBRE!D9+DICIEMBRE!D9 -> 72089133 | E9: =ENERO!E9+FEBRERO!E9+MARZO!E9+ABRIL!E9+MAYO!E9+JUNIO!E9+JULIO!E9+AGOSTO!E9+SEPTIEMBRE!E9+OCTUBRE!E9+NOVIEMBRE!E9+DICIEMBRE!E9 -> 293763.03 | F9: =ENERO!F9+FEBRERO!F9+MARZO!F9+ABRIL!F9+MAYO!F9+JUNIO!F9+JULIO!F9+AGOSTO!F9+SEPTIEMBRE!F9+OCTUBRE!F9+NOVIEMBRE!F9+DICIEMBRE!F9 -> 2021395.3 | G9: =ENERO!G9+FEBRERO!G9+MARZO!G9+ABRIL!G9+MAYO!G9+JUNIO!G9+JULIO!G9+AGOSTO!G9+SEPTIEMBRE!G9+OCTUBRE!G9+NOVIEMBRE!G9+DICIEMBRE!G9 -> 1047102.8 | H9: =ENERO!H9+FEBRERO!H9+MARZO!H9+ABRIL!H9+MAYO!H9+JUNIO!H9+JULIO!H9+AGOSTO!H9+SEPTIEMBRE!H9+OCTUBRE!H9+NOVIEMBRE!H9+DICIEMBRE!H9 -> 26841752 | I9: =ENERO!I9+FEBRERO!I9+MARZO!I9+ABRIL!I9+MAYO!I9+JUNIO!I9+JULIO!I9+AGOSTO!I9+SEPTIEMBRE!I9+OCTUBRE!I9+NOVIEMBRE!I9+DICIEMBRE!I9 -> 4672587.4 | ... M9: =ENERO!M9+FEBRERO!M9+MARZO!M9+ABRIL!M9+MAYO!M9+JUNIO!M9+JULIO!M9+AGOSTO!M9+SEPTIEMBRE!M9+OCTUBRE!M9+NOVIEMBRE!M9+DICIEMBRE!M9 -> 15512.2 | N9: =SUM(B9:M9) -> 6.6388558e+08
A10: ALBERTI | B10: =ENERO!B10+FEBRERO!B10+MARZO!B10+ABRIL!B10+MAYO!B10+JUNIO!B10+JULIO!B10+AGOSTO!B10+SEPTIEMBRE!B10+OCTUBRE!B10+NOVIEMBRE!B10+DICIEMBRE!B10 -> 3.7154145e+08 | C10: =ENERO!C10+FEBRERO!C10+MARZO!C10+ABRIL!C10+MAYO!C10+JUNIO!C10+JULIO!C10+AGOSTO!C10+SEPTIEMBRE!C10+OCTUBRE!C10+NOVIEMBRE!C10+DICIEMBRE!C10 -> 0 | D10: =ENERO!D10+FEBRERO!D10+MARZO!D10+ABRIL!D10+MAYO!D10+JUNIO!D10+JULIO!D10+AGOSTO!D10+SEPTIEMBRE!D10+OCTUBRE!D10+NOVIEMBRE!D10+DICIEMBRE!D10 -> 54679789 | E10: =ENERO!E10+FEBRERO!E10+MARZO!E10+ABRIL!E10+MAYO!E10+JUNIO!E10+JULIO!E10+AGOSTO!E10+SEPTIEMBRE!E10+OCTUBRE!E10+NOVIEMBRE!E10+DICIEMBRE!E10 -> 219370.07 | F10: =ENERO!F10+FEBRERO!F10+MARZO!F10+ABRIL!F10+MAYO!F10+JUNIO!F10+JULIO!F10+AGOSTO!F10+SEPTIEMBRE!F10+OCTUBRE!F10+NOVIEMBRE!F10+DICIEMBRE!F10 -> 1412109.5 | G10: =ENERO!G10+FEBRERO!G10+MARZO!G10+ABRIL!G10+MAYO!G10+JUNIO!G10+JULIO!G10+AGOSTO!G10+SEPTIEMBRE!G10+OCTUBRE!G10+NOVIEMBRE!G10+DICIEMBRE!G10 -> 924714.15 | H10: =ENERO!H10+FEBRERO!H10+MARZO!H10+ABRIL!H10+MAYO!H10+JUNIO!H10+JULIO!H10+AGOSTO!H10+SEPTIEMBRE!H10+OCTUBRE!H10+NOVIEMBRE!H10+DICIEMBRE!H10 -> 19726435 | I10: =ENERO!I10+FEBRERO!I10+MARZO!I10+ABRIL!I10+MAYO!I10+JUNIO!I10+JULIO!I10+AGOSTO!I10+SEPTIEMBRE!I10+OCTUBRE!I10+NOVIEMBRE!I10+DICIEMBRE!I10 -> 3264183.4 | ... M10: =ENERO!M10+FEBRERO!M10+MARZO!M10+ABRIL!M10+MAYO!M10+JUNIO!M10+JULIO!M10+AGOSTO!M10+SEPTIEMBRE!M10+OCTUBRE!M10+NOVIEMBRE!M10+DICIEMBRE!M10 -> 10836.44 | N10: =SUM(B10:M10) -> 4.8212912e+08
A11: ALMIRANTE BROWN | B11: =ENERO!B11+FEBRERO!B11+MARZO!B11+ABRIL!B11+MAYO!B11+JUNIO!B11+JULIO!B11+AGOSTO!B11+SEPTIEMBRE!B11+OCTUBRE!B11+NOVIEMBRE!B11+DICIEMBRE!B11 -> 4.3024847e+09 | C11: =ENERO!C11+FEBRERO!C11+MARZO!C11+ABRIL!C11+MAYO!C11+JUNIO!C11+JULIO!C11+AGOSTO!C11+SEPTIEMBRE!C11+OCTUBRE!C11+NOVIEMBRE!C11+DICIEMBRE!C11 -> 0 | D11: =ENERO!D11+FEBRERO!D11+MARZO!D11+ABRIL!D11+MAYO!D11+JUNIO!D11+JULIO!D11+AGOSTO!D11+SEPTIEMBRE!D11+OCTUBRE!D11+NOVIEMBRE!D11+DICIEMBRE!D11 -> 43546576 | E11: =ENERO!E11+FEBRERO!E11+MARZO!E11+ABRIL!E11+MAYO!E11+JUNIO!E11+JULIO!E11+AGOSTO!E11+SEPTIEMBRE!E11+OCTUBRE!E11+NOVIEMBRE!E11+DICIEMBRE!E11 -> 3526341.9 | F11: =ENERO!F11+FEBRERO!F11+MARZO!F11+ABRIL!F11+MAYO!F11+JUNIO!F11+JULIO!F11+AGOSTO!F11+SEPTIEMBRE!F11+OCTUBRE!F11+NOVIEMBRE!F11+DICIEMBRE!F11 -> 1.5156881e+08 | G11: =ENERO!G11+FEBRERO!G11+MARZO!G11+ABRIL!G11+MAYO!G11+JUNIO!G11+JULIO!G11+AGOSTO!G11+SEPTIEMBRE!G11+OCTUBRE!G11+NOVIEMBRE!G11+DICIEMBRE!G11 -> 83798824 | H11: =ENERO!H11+FEBRERO!H11+MARZO!H11+ABRIL!H11+MAYO!H11+JUNIO!H11+JULIO!H11+AGOSTO!H11+SEPTIEMBRE!H11+OCTUBRE!H11+NOVIEMBRE!H11+DICIEMBRE!H11 -> 2.2843396e+08 | I11: =ENERO!I11+FEBRERO!I11+MARZO!I11+ABRIL!I11+MAYO!I11+JUNIO!I11+JULIO!I11+AGOSTO!I11+SEPTIEMBRE!I11+OCTUBRE!I11+NOVIEMBRE!I11+DICIEMBRE!I11 -> 3.5036121e+08 | ... M11: =ENERO!M11+FEBRERO!M11+MARZO!M11+ABRIL!M11+MAYO!M11+JUNIO!M11+JULIO!M11+AGOSTO!M11+SEPTIEMBRE!M11+OCTUBRE!M11+NOVIEMBRE!M11+DICIEMBRE!M11 -> 1163163.7 | N11: =SUM(B11:M11) -> 5.7360947e+09
A12: ARRECIFES | B12: =ENERO!B12+FEBRERO!B12+MARZO!B12+ABRIL!B12+MAYO!B12+JUNIO!B12+JULIO!B12+AGOSTO!B12+SEPTIEMBRE!B12+OCTUBRE!B12+NOVIEMBRE!B12+DICIEMBRE!B12 -> 6.4577935e+08 | C12: =ENERO!C12+FEBRERO!C12+MARZO!C12+ABRIL!C12+MAYO!C12+JUNIO!C12+JULIO!C12+AGOSTO!C12+SEPTIEMBRE!C12+OCTUBRE!C12+NOVIEMBRE!C12+DICIEMBRE!C12 -> 0 | D12: =ENERO!D12+FEBRERO!D12+MARZO!D12+ABRIL!D12+MAYO!D12+JUNIO!D12+JULIO!D12+AGOSTO!D12+SEPTIEMBRE!D12+OCTUBRE!D12+NOVIEMBRE!D12+DICIEMBRE!D12 -> 71710965 | E12: =ENERO!E12+FEBRERO!E12+MARZO!E12+ABRIL!E12+MAYO!E12+JUNIO!E12+JULIO!E12+AGOSTO!E12+SEPTIEMBRE!E12+OCTUBRE!E12+NOVIEMBRE!E12+DICIEMBRE!E12 -> 376394.91 | F12: =ENERO!F12+FEBRERO!F12+MARZO!F12+ABRIL!F12+MAYO!F12+JUNIO!F12+JULIO!F12+AGOSTO!F12+SEPTIEMBRE!F12+OCTUBRE!F12+NOVIEMBRE!F12+DICIEMBRE!F12 -> 5182513.6 | G12: =ENERO!G12+FEBRERO!G12+MARZO!G12+ABRIL!G12+MAYO!G12+JUNIO!G12+JULIO!G12+AGOSTO!G12+SEPTIEMBRE!G12+OCTUBRE!G12+NOVIEMBRE!G12+DICIEMBRE!G12 -> 2529365.2 | H12: =ENERO!H12+FEBRERO!H12+MARZO!H12+ABRIL!H12+MAYO!H12+JUNIO!H12+JULIO!H12+AGOSTO!H12+SEPTIEMBRE!H12+OCTUBRE!H12+NOVIEMBRE!H12+DICIEMBRE!H12 -> 34286684 | I12: =ENERO!I12+FEBRERO!I12+MARZO!I12+ABRIL!I12+MAYO!I12+JUNIO!I12+JULIO!I12+AGOSTO!I12+SEPTIEMBRE!I12+OCTUBRE!I12+NOVIEMBRE!I12+DICIEMBRE!I12 -> 11979719 | ... M12: =ENERO!M12+FEBRERO!M12+MARZO!M12+ABRIL!M12+MAYO!M12+JUNIO!M12+JULIO!M12+AGOSTO!M12+SEPTIEMBRE!M12+OCTUBRE!M12+NOVIEMBRE!M12+DICIEMBRE!M12 -> 39771.09 | N12: =SUM(B12:M12) -> 8.3350413e+08
A13: AVELLANEDA | B13: =ENERO!B13+FEBRERO!B13+MARZO!B13+ABRIL!B13+MAYO!B13+JUNIO!B13+JULIO!B13+AGOSTO!B13+SEPTIEMBRE!B13+OCTUBRE!B13+NOVIEMBRE!B13+DICIEMBRE!B13 -> 2.6108475e+09 | C13: =ENERO!C13+FEBRERO!C13+MARZO!C13+ABRIL!C13+MAYO!C13+JUNIO!C13+JULIO!C13+AGOSTO!C13+SEPTIEMBRE!C13+OCTUBRE!C13+NOVIEMBRE!C13+DICIEMBRE!C13 -> 0 | D13: =ENERO!D13+FEBRERO!D13+MARZO!D13+ABRIL!D13+MAYO!D13+JUNIO!D13+JULIO!D13+AGOSTO!D13+SEPTIEMBRE!D13+OCTUBRE!D13+NOVIEMBRE!D13+DICIEMBRE!D13 -> 35661686 | E13: =ENERO!E13+FEBRERO!E13+MARZO!E13+ABRIL!E13+MAYO!E13+JUNIO!E13+JULIO!E13+AGOSTO!E13+SEPTIEMBRE!E13+OCTUBRE!E13+NOVIEMBRE!E13+DICIEMBRE!E13 -> 2151192.3 | F13: =ENERO!F13+FEBRERO!F13+MARZO!F13+ABRIL!F13+MAYO!F13+JUNIO!F13+JULIO!F13+AGOSTO!F13+SEPTIEMBRE!F13+OCTUBRE!F13+NOVIEMBRE!F13+DICIEMBRE!F13 -> 73705666 | G13: =ENERO!G13+FEBRERO!G13+MARZO!G13+ABRIL!G13+MAYO!G13+JUNIO!G13+JULIO!G13+AGOSTO!G13+SEPTIEMBRE!G13+OCTUBRE!G13+NOVIEMBRE!G13+DICIEMBRE!G13 -> 20358428 | H13: =ENERO!H13+FEBRERO!H13+MARZO!H13+ABRIL!H13+MAYO!H13+JUNIO!H13+JULIO!H13+AGOSTO!H13+SEPTIEMBRE!H13+OCTUBRE!H13+NOVIEMBRE!H13+DICIEMBRE!H13 -> 1.3861902e+08 | I13: =ENERO!I13+FEBRERO!I13+MARZO!I13+ABRIL!I13+MAYO!I13+JUNIO!I13+JULIO!I13+AGOSTO!I13+SEPTIEMBRE!I13+OCTUBRE!I13+NOVIEMBRE!I13+DICIEMBRE!I13 -> 1.7037546e+08 | ... M13: =ENERO!M13+FEBRERO!M13+MARZO!M13+ABRIL!M13+MAYO!M13+JUNIO!M13+JULIO!M13+AGOSTO!M13+SEPTIEMBRE!M13+OCTUBRE!M13+NOVIEMBRE!M13+DICIEMBRE!M13 -> 565629.04 | N13: =SUM(B13:M13) -> 3.4914739e+09
A14: AYACUCHO | B14: =ENERO!B14+FEBRERO!B14+MARZO!B14+ABRIL!B14+MAYO!B14+JUNIO!B14+JULIO!B14+AGOSTO!B14+SEPTIEMBRE!B14+OCTUBRE!B14+NOVIEMBRE!B14+DICIEMBRE!B14 -> 9.4619525e+08 | C14: =ENERO!C14+FEBRERO!C14+MARZO!C14+ABRIL!C14+MAYO!C14+JUNIO!C14+JULIO!C14+AGOSTO!C14+SEPTIEMBRE!C14+OCTUBRE!C14+NOVIEMBRE!C14+DICIEMBRE!C14 -> 0 | D14: =ENERO!D14+FEBRERO!D14+MARZO!D14+ABRIL!D14+MAYO!D14+JUNIO!D14+JULIO!D14+AGOSTO!D14+SEPTIEMBRE!D14+OCTUBRE!D14+NOVIEMBRE!D14+DICIEMBRE!D14 -> 1.2473278e+08 | E14: =ENERO!E14+FEBRERO!E14+MARZO!E14+ABRIL!E14+MAYO!E14+JUNIO!E14+JULIO!E14+AGOSTO!E14+SEPTIEMBRE!E14+OCTUBRE!E14+NOVIEMBRE!E14+DICIEMBRE!E14 -> 550592.62 | F14: =ENERO!F14+FEBRERO!F14+MARZO!F14+ABRIL!F14+MAYO!F14+JUNIO!F14+JULIO!F14+AGOSTO!F14+SEPTIEMBRE!F14+OCTUBRE!F14+NOVIEMBRE!F14+DICIEMBRE!F14 -> 3354656.1 | G14: =ENERO!G14+FEBRERO!G14+MARZO!G14+ABRIL!G14+MAYO!G14+JUNIO!G14+JULIO!G14+AGOSTO!G14+SEPTIEMBRE!G14+OCTUBRE!G14+NOVIEMBRE!G14+DICIEMBRE!G14 -> 1767835.9 | H14: =ENERO!H14+FEBRERO!H14+MARZO!H14+ABRIL!H14+MAYO!H14+JUNIO!H14+JULIO!H14+AGOSTO!H14+SEPTIEMBRE!H14+OCTUBRE!H14+NOVIEMBRE!H14+DICIEMBRE!H14 -> 50236816 | I14: =ENERO!I14+FEBRERO!I14+MARZO!I14+ABRIL!I14+MAYO!I14+JUNIO!I14+JULIO!I14+AGOSTO!I14+SEPTIEMBRE!I14+OCTUBRE!I14+NOVIEMBRE!I14+DICIEMBRE!I14 -> 7754506.8 | ... M14: =ENERO!M14+FEBRERO!M14+MARZO!M14+ABRIL!M14+MAYO!M14+JUNIO!M14+JULIO!M14+AGOSTO!M14+SEPTIEMBRE!M14+OCTUBRE!M14+NOVIEMBRE!M14+DICIEMBRE!M14 -> 25743.79 | N14: =SUM(B14:M14) -> 1.2230122e+09
A15: AZUL | B15: =ENERO!B15+FEBRERO!B15+MARZO!B15+ABRIL!B15+MAYO!B15+JUNIO!B15+JULIO!B15+AGOSTO!B15+SEPTIEMBRE!B15+OCTUBRE!B15+NOVIEMBRE!B15+DICIEMBRE!B15 -> 1.5420191e+09 | C15: =ENERO!C15+FEBRERO!C15+MARZO!C15+ABRIL!C15+MAYO!C15+JUNIO!C15+JULIO!C15+AGOSTO!C15+SEPTIEMBRE!C15+OCTUBRE!C15+NOVIEMBRE!C15+DICIEMBRE!C15 -> 0 | D15: =ENERO!D15+FEBRERO!D15+MARZO!D15+ABRIL!D15+MAYO!D15+JUNIO!D15+JULIO!D15+AGOSTO!D15+SEPTIEMBRE!D15+OCTUBRE!D15+NOVIEMBRE!D15+DICIEMBRE!D15 -> 1.8487994e+08 | E15: =ENERO!E15+FEBRERO!E15+MARZO!E15+ABRIL!E15+MAYO!E15+JUNIO!E15+JULIO!E15+AGOSTO!E15+SEPTIEMBRE!E15+OCTUBRE!E15+NOVIEMBRE!E15+DICIEMBRE!E15 -> 900825.55 | F15: =ENERO!F15+FEBRERO!F15+MARZO!F15+ABRIL!F15+MAYO!F15+JUNIO!F15+JULIO!F15+AGOSTO!F15+SEPTIEMBRE!F15+OCTUBRE!F15+NOVIEMBRE!F15+DICIEMBRE!F15 -> 12497528 | G15: =ENERO!G15+FEBRERO!G15+MARZO!G15+ABRIL!G15+MAYO!G15+JUNIO!G15+JULIO!G15+AGOSTO!G15+SEPTIEMBRE!G15+OCTUBRE!G15+NOVIEMBRE!G15+DICIEMBRE!G15 -> 5684272.3 | H15: =ENERO!H15+FEBRERO!H15+MARZO!H15+ABRIL!H15+MAYO!H15+JUNIO!H15+JULIO!H15+AGOSTO!H15+SEPTIEMBRE!H15+OCTUBRE!H15+NOVIEMBRE!H15+DICIEMBRE!H15 -> 81871188 | I15: =ENERO!I15+FEBRERO!I15+MARZO!I15+ABRIL!I15+MAYO!I15+JUNIO!I15+JULIO!I15+AGOSTO!I15+SEPTIEMBRE!I15+OCTUBRE!I15+NOVIEMBRE!I15+DICIEMBRE!I15 -> 28888852 | ... M15: =ENERO!M15+FEBRERO!M15+MARZO!M15+ABRIL!M15+MAYO!M15+JUNIO!M15+JULIO!M15+AGOSTO!M15+SEPTIEMBRE!M15+OCTUBRE!M15+NOVIEMBRE!M15+DICIEMBRE!M15 -> 95907.74 | N15: =SUM(B15:M15) -> 2.0044224e+09
A16: BAHIA BLANCA | B16: =ENERO!B16+FEBRERO!B16+MARZO!B16+ABRIL!B16+MAYO!B16+JUNIO!B16+JULIO!B16+AGOSTO!B16+SEPTIEMBRE!B16+OCTUBRE!B16+NOVIEMBRE!B16+DICIEMBRE!B16 -> 2.8502779e+09 | C16: =ENERO!C16+FEBRERO!C16+MARZO!C16+ABRIL!C16+MAYO!C16+JUNIO!C16+JULIO!C16+AGOSTO!C16+SEPTIEMBRE!C16+OCTUBRE!C16+NOVIEMBRE!C16+DICIEMBRE!C16 -> 0 | D16: =ENERO!D16+FEBRERO!D16+MARZO!D16+ABRIL!D16+MAYO!D16+JUNIO!D16+JULIO!D16+AGOSTO!D16+SEPTIEMBRE!D16+OCTUBRE!D16+NOVIEMBRE!D16+DICIEMBRE!D16 -> 86999370 | E16: =ENERO!E16+FEBRERO!E16+MARZO!E16+ABRIL!E16+MAYO!E16+JUNIO!E16+JULIO!E16+AGOSTO!E16+SEPTIEMBRE!E16+OCTUBRE!E16+NOVIEMBRE!E16+DICIEMBRE!E16 -> 2339592.8 | F16: =ENERO!F16+FEBRERO!F16+MARZO!F16+ABRIL!F16+MAYO!F16+JUNIO!F16+JULIO!F16+AGOSTO!F16+SEPTIEMBRE!F16+OCTUBRE!F16+NOVIEMBRE!F16+DICIEMBRE!F16 -> 46610366 | G16: =ENERO!G16+FEBRERO!G16+MARZO!G16+ABRIL!G16+MAYO!G16+JUNIO!G16+JULIO!G16+AGOSTO!G16+SEPTIEMBRE!G16+OCTUBRE!G16+NOVIEMBRE!G16+DICIEMBRE!G16 -> 26245563 | H16: =ENERO!H16+FEBRERO!H16+MARZO!H16+ABRIL!H16+MAYO!H16+JUNIO!H16+JULIO!H16+AGOSTO!H16+SEPTIEMBRE!H16+OCTUBRE!H16+NOVIEMBRE!H16+DICIEMBRE!H16 -> 1.5133122e+08 | I16: =ENERO!I16+FEBRERO!I16+MARZO!I16+ABRIL!I16+MAYO!I16+JUNIO!I16+JULIO!I16+AGOSTO!I16+SEPTIEMBRE!I16+OCTUBRE!I16+NOVIEMBRE!I16+DICIEMBRE!I16 -> 1.0774291e+08 | ... M16: =ENERO!M16+FEBRERO!M16+MARZO!M16+ABRIL!M16+MAYO!M16+JUNIO!M16+JULIO!M16+AGOSTO!M16+SEPTIEMBRE!M16+OCTUBRE!M16+NOVIEMBRE!M16+DICIEMBRE!M16 -> 357695.25 | N16: =SUM(B16:M16) -> 3.637763e+09
A17: BALCARCE | B17: =ENERO!B17+FEBRERO!B17+MARZO!B17+ABRIL!B17+MAYO!B17+JUNIO!B17+JULIO!B17+AGOSTO!B17+SEPTIEMBRE!B17+OCTUBRE!B17+NOVIEMBRE!B17+DICIEMBRE!B17 -> 1.0241498e+09 | C17: =ENERO!C17+FEBRERO!C17+MARZO!C17+ABRIL!C17+MAYO!C17+JUNIO!C17+JULIO!C17+AGOSTO!C17+SEPTIEMBRE!C17+OCTUBRE!C17+NOVIEMBRE!C17+DICIEMBRE!C17 -> 0 | D17: =ENERO!D17+FEBRERO!D17+MARZO!D17+ABRIL!D17+MAYO!D17+JUNIO!D17+JULIO!D17+AGOSTO!D17+SEPTIEMBRE!D17+OCTUBRE!D17+NOVIEMBRE!D17+DICIEMBRE!D17 -> 1.684122e+08 | E17: =ENERO!E17+FEBRERO!E17+MARZO!E17+ABRIL!E17+MAYO!E17+JUNIO!E17+JULIO!E17+AGOSTO!E17+SEPTIEMBRE!E17+OCTUBRE!E17+NOVIEMBRE!E17+DICIEMBRE!E17 -> 595271.58 | F17: =ENERO!F17+FEBRERO!F17+MARZO!F17+ABRIL!F17+MAYO!F17+JUNIO!F17+JULIO!F17+AGOSTO!F17+SEPTIEMBRE!F17+OCTUBRE!F17+NOVIEMBRE!F17+DICIEMBRE!F17 -> 9572955.6 | G17: =ENERO!G17+FEBRERO!G17+MARZO!G17+ABRIL!G17+MAYO!G17+JUNIO!G17+JULIO!G17+AGOSTO!G17+SEPTIEMBRE!G17+OCTUBRE!G17+NOVIEMBRE!G17+DICIEMBRE!G17 -> 3807646.5 | H17: =ENERO!H17+FEBRERO!H17+MARZO!H17+ABRIL!H17+MAYO!H17+JUNIO!H17+JULIO!H17+AGOSTO!H17+SEPTIEMBRE!H17+OCTUBRE!H17+NOVIEMBRE!H17+DICIEMBRE!H17 -> 54375697 | I17: =ENERO!I17+FEBRERO!I17+MARZO!I17+ABRIL!I17+MAYO!I17+JUNIO!I17+JULIO!I17+AGOSTO!I17+SEPTIEMBRE!I17+OCTUBRE!I17+NOVIEMBRE!I17+DICIEMBRE!I17 -> 22128512 | ... M17: =ENERO!M17+FEBRERO!M17+MARZO!M17+ABRIL!M17+MAYO!M17+JUNIO!M17+JULIO!M17+AGOSTO!M17+SEPTIEMBRE!M17+OCTUBRE!M17+NOVIEMBRE!M17+DICIEMBRE!M17 -> 73464.12 | N17: =SUM(B17:M17) -> 1.3840155e+09
